Workbook

Sheet Sheet1
A1: s
A2: id | B2: Country | C2: City | D2: Line | E2: Phase | F2: Start year | G2: End year | H2: RR? | I2: Length | J2: TunnelPer | K2: Tunnel | L2: Elevated | M2: Atgrade | N2: Stations | O2: Platform Length (Meters) | P2: Source1 | Q2: Cost | R2: Currency | S2: Year | T2: PPP rate | U2: Real cost | V2: Cost/km (Millions) | W2: Cheap? | X2: Clength | Y2: Ctunnel | Z2: Anglo? | AA2: Inflation Index | AB2: Real cost (2025 dollars) | AC2: Cost/km (2025 dollars) | AD2: Source2 | AE2: Reference
A3: 8200 | B3: AE | C3: Dubai | D3: Phase 1 | E3: Phase 1 - Red Line | F3: 2005 | G3: 2010 | H3: 0 | I3: 35 | J3: =K3/I3 -> 0.13428571 | K3: 4.7 | L3: 0 | M3: 0 | N3: 29 | P3: Trade | Q3: 4200 | R3: USD | S3: 2005 | T3: 1.8 | U3: =Q3*T3 -> 7560 | V3: =U3/I3 -> 216 | W3: =IF(OR(B3 = "BG",B3 = "GR",B3 = "IT",B3 = "ES",B3 = "PT",B3 = "TR", B3 = "KR",B3 = "SE",B3 = "CH",B3 = "NO",B3 = "DK",B3 = "FI"), 1, 0) -> 0 | X3: =W3*I3 -> 0 | Y3: =W3*K3 -> 0 | Z3: =IF(OR(B3 = "US",B3 = "CA",B3 = "UK",B3 = "NZ",B3 = "AU",B3 = "SG"), 1, 0) -> 0 | AA3: =VLOOKUP(S3,CPI!$A$2:$F$71,6,0) -> 1.6493318 | AB3: =U3*AA3 -> 12468.948 | AC3: =V3*AA3 -> 356.25567
A4: 8201 | B4: AE | C4: Dubai | D4: Phase 2 | E4: Phase 2 - Green Line | F4: 2006 | G4: 2010 | H4: 0 | I4: 22.5 | J4: =K4/I4 -> 0.35111111 | K4: 7.9 | L4: 0 | M4: 0 | N4: 20 | Q4: 3600 | R4: USD | S4: 2006 | T4: 1.9 | U4: =Q4*T4 -> 6840 | V4: =U4/I4 -> 304 | W4: =IF(OR(B4 = "BG",B4 = "GR",B4 = "IT",B4 = "ES",B4 = "PT",B4 = "TR", B4 = "KR",B4 = "SE",B4 = "CH",B4 = "NO",B4 = "DK",B4 = "FI"), 1, 0) -> 0 | X4: =W4*I4 -> 0 | Y4: =W4*K4 -> 0 | Z4: =IF(OR(B4 = "US",B4 = "CA",B4 = "UK",B4 = "NZ",B4 = "AU",B4 = "SG"), 1, 0) -> 0 | AA4: =VLOOKUP(S4,CPI!$A$2:$F$71,6,0) -> 1.5977902 | AB4: =U4*AA4 -> 10928.885 | AC4: =V4*AA4 -> 485.72821
A5: 8202 | B5: AE | C5: Dubai | D5: Red Line | E5: Phase 3 (Red Line Extension/Route 2020) | F5: 2016 | G5: 2020 | H5: 0 | I5: 15 | J5: =K5/I5 -> 0.21333333 | K5: 3.2 | L5: 0 | M5: 0 | N5: 7 | P5: Trade | Q5: 2900 | R5: USD | S5: 2016 | T5: 1.9 | U5: =Q5*T5 -> 5510 | V5: =U5/I5 -> 367.33333 | W5: =IF(OR(B5 = "BG",B5 = "GR",B5 = "IT",B5 = "ES",B5 = "PT",B5 = "TR", B5 = "KR",B5 = "SE",B5 = "CH",B5 = "NO",B5 = "DK",B5 = "FI"), 1, 0) -> 0 | X5: =W5*I5 -> 0 | Y5: =W5*K5 -> 0 | Z5: =IF(OR(B5 = "US",B5 = "CA",B5 = "UK",B5 = "NZ",B5 = "AU",B5 = "SG"), 1, 0) -> 0 | AA5: =VLOOKUP(S5,CPI!$A$2:$F$71,6,0) -> 1.3421046 | AB5: =U5*AA5 -> 7394.9964 | AC5: =V5*AA5 -> 492.99976 | AD5: Media | AE5: https://www.railway-technology.com/projects/route-2020-dubai/
A6: 7593 | B6: AR | C6: Buenos Aires | D6: RER | E6: RER | F6: 2020 | G6: 2026 | H6: 1 | I6: 20 | J6: 1 | K6: 20 | L6: 0 | M6: 0 | N6: 4 | P6: Media | Q6: 2300 | R6: USD | S6: 2023 | T6: 2.02 | U6: =Q6*T6 -> 4646 | V6: =U6/I6 -> 232.3 | W6: =IF(OR(B6 = "BG",B6 = "GR",B6 = "IT",B6 = "ES",B6 = "PT",B6 = "TR", B6 = "KR",B6 = "SE",B6 = "CH",B6 = "NO",B6 = "DK",B6 = "FI"), 1, 0) -> 0 | X6: =W6*I6 -> 0 | Y6: =W6*K6 -> 0 | Z6: =IF(OR(B6 = "US",B6 = "CA",B6 = "UK",B6 = "NZ",B6 = "AU",B6 = "SG"), 1, 0) -> 0 | AA6: =VLOOKUP(S6,CPI!$A$2:$F$71,6,0) -> 1.057146 | AB6: =U6*AA6 -> 4911.5003 | AC6: =V6*AA6 -> 245.57502 | AD6: Media | AE6: https://tn.com.ar/economia/el-gobierno-relanzo-el-rer-el-proyecto-para-conectar-los-trenes-del-area-metropolitana_856411
A7: 9753 | B7: AT | C7: Vienna | D7: va | E7: Lainz Tunnel | F7: 1999 | G7: 2012 | H7: 1 | I7: 12.8 | J7: 1 | K7: 12.8 | L7: 0 | M7: 0 | N7: 0 | P7: Media | Q7: 1300 | R7: EUR | S7: 2005 | T7: 1.25 | U7: =Q7*T7 -> 1625 | V7: =U7/I7 -> 126.95312 | W7: =IF(OR(B7 = "BG",B7 = "GR",B7 = "IT",B7 = "ES",B7 = "PT",B7 = "TR", B7 = "KR",B7 = "SE",B7 = "CH",B7 = "NO",B7 = "DK",B7 = "FI"), 1, 0) -> 0 | X7: =W7*I7 -> 0 | Y7: =W7*K7 -> 0 | Z7: =IF(OR(B7 = "US",B7 = "CA",B7 = "UK",B7 = "NZ",B7 = "AU",B7 = "SG"), 1, 0) -> 0 | AA7: =VLOOKUP(S7,CPI!$A$2:$F$71,6,0) -> 1.6493318 | AB7: =U7*AA7 -> 2680.1642 | AC7: =V7*AA7 -> 209.38783 | AD7: Media | AE7: https://wien.orf.at/v2/news/stories/2537074/
A8: 7360 | B8: AT | C8: Vienna | D8: Line 2 | E8: Line 2 extension | F8: 2010 | G8: 2013 | H8: 0 | I8: 4.2 | J8: 0 | K8: 0 | L8: 2.63 | M8: 1.57 | N8: 3 | P8: Media | Q8: 320 | R8: EUR | S8: 2012 | T8: 1.3 | U8: =Q8*T8 -> 416 | V8: =U8/I8 -> 99.047619 | W8: =IF(OR(B8 = "BG",B8 = "GR",B8 = "IT",B8 = "ES",B8 = "PT",B8 = "TR", B8 = "KR",B8 = "SE",B8 = "CH",B8 = "NO",B8 = "DK",B8 = "FI"), 1, 0) -> 0 | X8: =W8*I8 -> 0 | Y8: =W8*K8 -> 0 | Z8: =IF(OR(B8 = "US",B8 = "CA",B8 = "UK",B8 = "NZ",B8 = "AU",B8 = "SG"), 1, 0) -> 0 | AA8: =VLOOKUP(S8,CPI!$A$2:$F$71,6,0) -> 1.4029744 | AB8: =U8*AA8 -> 583.63734 | AC8: =V8*AA8 -> 138.96127 | AD8: Media | AE8: https://wien.orf.at/news/stories/2607445/
A9: 7361 | B9: AT | C9: Vienna | D9: Line 1 | E9: Line 1 extension | F9: 2012 | G9: 2017 | H9: 0 | I9: 4.7 | J9: 0.57 | K9: 2.7 | L9: 0.06 | M9: 2.008 | N9: 5 | P9: Measured | Q9: 600 | R9: EUR | S9: 2015 | T9: 1.3 | U9: =Q9*T9 -> 780 | V9: =U9/I9 -> 165.95745 | W9: =IF(OR(B9 = "BG",B9 = "GR",B9 = "IT",B9 = "ES",B9 = "PT",B9 = "TR", B9 = "KR",B9 = "SE",B9 = "CH",B9 = "NO",B9 = "DK",B9 = "FI"), 1, 0) -> 0 | X9: =W9*I9 -> 0 | Y9: =W9*K9 -> 0 | Z9: =IF(OR(B9 = "US",B9 = "CA",B9 = "UK",B9 = "NZ",B9 = "AU",B9 = "SG"), 1, 0) -> 0 | AA9: =VLOOKUP(S9,CPI!$A$2:$F$71,6,0) -> 1.3590354 | AB9: =U9*AA9 -> 1060.0476 | AC9: =V9*AA9 -> 225.54205 | AD9: Plan | AE9: https://www.wien.gv.at/stadtentwicklung/projekte/verkehrsplanung/u-bahn/u1-oberlaa.html
A10: 7362 | B10: AT | C10: Vienna | D10: U2/U5 cross | E10: U2/U5 cross | F10: 2019 | G10: 2029 | H10: 0 | I10: 9 | J10: 1 | K10: 9 | L10: 0 | M10: 0 | N10: 11 | P10: Plan | Q10: 2200 | R10: EUR | S10: 2023 | T10: 1.3 | U10: =Q10*T10 -> 2860 | V10: =U10/I10 -> 317.77778 | W10: =IF(OR(B10 = "BG",B10 = "GR",B10 = "IT",B10 = "ES",B10 = "PT",B10 = "TR", B10 = "KR",B10 = "SE",B10 = "CH",B10 = "NO",B10 = "DK",B10 = "FI"), 1, 0) -> 0 | X10: =W10*I10 -> 0 | Y10: =W10*K10 -> 0 | Z10: =IF(OR(B10 = "US",B10 = "CA",B10 = "UK",B10 = "NZ",B10 = "AU",B10 = "SG"), 1, 0) -> 0 | AA10: =VLOOKUP(S10,CPI!$A$2:$F$71,6,0) -> 1.057146 | AB10: =U10*AA10 -> 3023.4376 | AC10: =V10*AA10 -> 335.93751 | AD10: Media | AE10: https://wien.orf.at/news/stories/2940360/
A11: 7280 | B11: AU | C11: Melbourne | D11: Metro Tunnel | E11: Metro Tunnel | F11: 2018 | G11: 2025 | H11: 0 | I11: 9 | J11: 1 | K11: 9 | L11: 0 | M11: 0 | N11: 5 | P11: Plan | Q11: 12584.4 | R11: AUD | S11: 2021 | T11: 0.69 | U11: =Q11*T11 -> 8683.236 | V11: =U11/I11 -> 964.804 | W11: =IF(OR(B11 = "BG",B11 = "GR",B11 = "IT",B11 = "ES",B11 = "PT",B11 = "TR", B11 = "KR",B11 = "SE",B11 = "CH",B11 = "NO",B11 = "DK",B11 = "FI"), 1, 0) -> 0 | X11: =W11*I11 -> 0 | Y11: =W11*K11 -> 0 | Z11: =IF(OR(B11 = "US",B11 = "CA",B11 = "UK",B11 = "NZ",B11 = "AU",B11 = "SG"), 1, 0) -> 1 | AA11: =VLOOKUP(S11,CPI!$A$2:$F$71,6,0) -> 1.188746 | AB11: =U11*AA11 -> 10322.162 | AC11: =V11*AA11 -> 1146.9069 | AD11: Plan | AE11: https://www.audit.vic.gov.au/report/melbourne-metro-tunnel-project-phase-2-main-works?section=
A12: 7587 | B12: AU | C12: Perth | D12: Forrestfield-Airport Link | E12: Forrestfield-Airport Link | F12: 2016 | G12: 2021 | H12: 1 | I12: 8.5 | J12: 1 | K12: 8.5 | L12: 0 | M12: 0 | N12: 3 | P12: Plan | Q12: 1860 | R12: AUD | S12: 2018 | T12: 0.69 | U12: =Q12*T12 -> 1283.4 | V12: =U12/I12 -> 150.98824 | W12: =IF(OR(B12 = "BG",B12 = "GR",B12 = "IT",B12 = "ES",B12 = "PT",B12 = "TR", B12 = "KR",B12 = "SE",B12 = "CH",B12 = "NO",B12 = "DK",B12 = "FI"), 1, 0) -> 0 | X12: =W12*I12 -> 0 | Y12: =W12*K12 -> 0 | Z12: =IF(OR(B12 = "US",B12 = "CA",B12 = "UK",B12 = "NZ",B12 = "AU",B12 = "SG"), 1, 0) -> 1 | AA12: =VLOOKUP(S12,CPI!$A$2:$F$71,6,0) -> 1.2827779 | AB12: =U12*AA12 -> 1646.3171 | AC12: =V12*AA12 -> 193.68437 | AD12: Plan | AE12: https://www.forrestfieldairportlink.wa.gov.au/Portals/14/Project%20Overview%20Fact%20Sheet%20-%20Dec18%20WEB.pdf
A13: 7275 | B13: AU | C13: Sydney | D13: Metro NW | E13: Metro NW | F13: 2013 | G13: 2019 | H13: 0 | I13: 36 | J13: 0.42 | K13: 15.1 | L13: 0 | M13: 0 | N13: 13 | P13: Wiki | Q13: 7800 | R13: AUD | S13: 2016 | T13: 0.69 | U13: =Q13*T13 -> 5382 | V13: =U13/I13 -> 149.5 | W13: =IF(OR(B13 = "BG",B13 = "GR",B13 = "IT",B13 = "ES",B13 = "PT",B13 = "TR", B13 = "KR",B13 = "SE",B13 = "CH",B13 = "NO",B13 = "DK",B13 = "FI"), 1, 0) -> 0 | X13: =W13*I13 -> 0 | Y13: =W13*K13 -> 0 | Z13: =IF(OR(B13 = "US",B13 = "CA",B13 = "UK",B13 = "NZ",B13 = "AU",B13 = "SG"), 1, 0) -> 1 | AA13: =VLOOKUP(S13,CPI!$A$2:$F$71,6,0) -> 1.3421046 | AB13: =U13*AA13 -> 7223.207 | AC13: =V13*AA13 -> 200.64464 | AD13: Plan | AE13: https://www.transport.nsw.gov.au/news-and-events/media-releases/sydney-metro-northwest-under-budget
A14: 7274 | B14: AU | C14: Sydney | D14: Metro City & SW | E14: Metro City & SW | F14: 2017 | G14: 2024 | H14: 0 | I14: 30 | J14: 0.51 | K14: 15.3 | L14: 0 | M14: 0 | N14: 7 | P14: Wiki | Q14: 15500 | R14: AUD | S14: 2021 | T14: 0.69 | U14: =Q14*T14 -> 10695 | V14: =U14/I14 -> 356.5 | W14: =IF(OR(B14 = "BG",B14 = "GR",B14 = "IT",B14 = "ES",B14 = "PT",B14 = "TR", B14 = "KR",B14 = "SE",B14 = "CH",B14 = "NO",B14 = "DK",B14 = "FI"), 1, 0) -> 0 | X14: =W14*I14 -> 0 | Y14: =W14*K14 -> 0 | Z14: =IF(OR(B14 = "US",B14 = "CA",B14 = "UK",B14 = "NZ",B14 = "AU",B14 = "SG"), 1, 0) -> 1 | AA14: =VLOOKUP(S14,CPI!$A$2:$F$71,6,0) -> 1.188746 | AB14: =U14*AA14 -> 12713.638 | AC14: =V14*AA14 -> 423.78794 | AD14: Media | AE14: https://www.abc.net.au/news/2020-02-21/nsw-government-confirms-three-billion-metro-budget-blowout/11986968
A15: 7464 | B15: BD | C15: Dhaka | D15: Line 6 | E15: Line 6 | F15: 2015 | G15: 2022 | H15: 0 | I15: 21.3 | J15: 0 | K15: 0 | L15: 0 | M15: 0 | N15: 16 | P15: Media | Q15: 334720 | R15: BDT | S15: 2019 | T15: 0.032 | U15: =Q15*T15 -> 10711.04 | V15: =U15/I15 -> 502.86573 | W15: =IF(OR(B15 = "BG",B15 = "GR",B15 = "IT",B15 = "ES",B15 = "PT",B15 = "TR", B15 = "KR",B15 = "SE",B15 = "CH",B15 = "NO",B15 = "DK",B15 = "FI"), 1, 0) -> 0 | X15: =W15*I15 -> 0 | Y15: =W15*K15 -> 0 | Z15: =IF(OR(B15 = "US",B15 = "CA",B15 = "UK",B15 = "NZ",B15 = "AU",B15 = "SG"), 1, 0) -> 0 | AA15: =VLOOKUP(S15,CPI!$A$2:$F$71,6,0) -> 1.2599479 | AB15: =U15*AA15 -> 13495.352 | AC15: =V15*AA15 -> 633.58462 | AD15: Media | AE15: https://www.thedailystar.net/news/bangladesh/transport/news/metro-now-set-cost-50pc-more-3072816
A16: 7465 | B16: BD | C16: Dhaka | D16: Line 1 | E16: Line 1 | F16: 2020 | G16: 2026 | H16: 0 | I16: 31.2 | J16: 0.64 | K16: 19.9 | L16: 0 | M16: 0 | N16: 19 | P16: Media | Q16: 525610 | R16: BDT | S16: 2023 | T16: 0.032 | U16: =Q16*T16 -> 16819.52 | V16: =U16/I16 -> 539.08718 | W16: =IF(OR(B16 = "BG",B16 = "GR",B16 = "IT",B16 = "ES",B16 = "PT",B16 = "TR", B16 = "KR",B16 = "SE",B16 = "CH",B16 = "NO",B16 = "DK",B16 = "FI"), 1, 0) -> 0 | X16: =W16*I16 -> 0 | Y16: =W16*K16 -> 0 | Z16: =IF(OR(B16 = "US",B16 = "CA",B16 = "UK",B16 = "NZ",B16 = "AU",B16 = "SG"), 1, 0) -> 0 | AA16: =VLOOKUP(S16,CPI!$A$2:$F$71,6,0) -> 1.057146 | AB16: =U16*AA16 -> 17780.688 | AC16: =V16*AA16 -> 569.89385 | AD16: Media | AE16: https://bdnews24.com/economy/2019/10/15/govt-approves-two-more-metro-rail-projects-worth-tk-938bn
A17: 7466 | B17: BD | C17: Dhaka | D17: Line 5 | E17: Line 5 | F17: 2020 | G17: 2028 | H17: 0 | I17: 19.6 | J17: 0.7 | K17: 14 | L17: 0 | M17: 0 | N17: 14 | P17: Media | Q17: 412380 | R17: BDT | S17: 2024 | T17: 0.032 | U17: =Q17*T17 -> 13196.16 | V17: =U17/I17 -> 673.27347 | W17: =IF(OR(B17 = "BG",B17 = "GR",B17 = "IT",B17 = "ES",B17 = "PT",B17 = "TR", B17 = "KR",B17 = "SE",B17 = "CH",B17 = "NO",B17 = "DK",B17 = "FI"), 1, 0) -> 0 | X17: =W17*I17 -> 0 | Y17: =W17*K17 -> 0 | Z17: =IF(OR(B17 = "US",B17 = "CA",B17 = "UK",B17 = "NZ",B17 = "AU",B17 = "SG"), 1, 0) -> 0 | AA17: =VLOOKUP(S17,CPI!$A$2:$F$71,6,0) -> 1 | AB17: =U17*AA17 -> 13196.16 | AC17: =V17*AA17 -> 673.27347 | AD17: Media | AE17: https://bdnews24.com/economy/2019/10/15/govt-approves-two-more-metro-rail-projects-worth-tk-938bn
... A23: 7177 | B23: BG | C23: Sofia | D23: Line 3 | E23: Line 3 extension (Third Stage) | F23: 2021 | G23: 2026 | H23: 0 | I23: 3.1 | J23: 1 | K23: 3.1 | L23: 0 | M23: 0 | N23: 4 | P23: Plan | Q23: 112.5 | R23: EUR | S23: 2021 | T23: 3.32 | U23: =Q23*T23 -> 373.5 | V23: =U23/I23 -> 120.48387 | W23: =IF(OR(B23 = "BG",B23 = "GR",B23 = "IT",B23 = "ES",B23 = "PT",B23 = "TR", B23 = "KR",B23 = "SE",B23 = "CH",B23 = "NO",B23 = "DK",B23 = "FI"), 1, 0) -> 1 | X23: =W23*I23 -> 3.1 | Y23: =W23*K23 -> 3.1 | Z23: =IF(OR(B23 = "US",B23 = "CA",B23 = "UK",B23 = "NZ",B23 = "AU",B23 = "SG"), 1, 0) -> 0 | AA23: =VLOOKUP(S23,CPI!$A$2:$F$71,6,0) -> 1.188746 | AB23: =U23*AA23 -> 443.99663 | AC23: =V23*AA23 -> 143.22472 | AD23: Trade | AE23: https://seenews.com/news/sofia-opens-1125-mln-euro-tender-for-subway-expansion-681553
A24: 7168 | B24: BG | C24: Sofia | D24: Line 1 | E24: Line 1 northern | F24: 2009 | G24: cond | H24: 0 | I24: 5.1 | J24: 0.6 | K24: 3.1 | L24: 0 | M24: 0 | N24: 4 | P24: Measured | Q24: 407 | R24: BGN | S24: 2010 | T24: 1.69 | U24: =Q24*T24 -> 687.83 | V24: =U24/I24 -> 134.86863 | W24: =IF(OR(B24 = "BG",B24 = "GR",B24 = "IT",B24 = "ES",B24 = "PT",B24 = "TR", B24 = "KR",B24 = "SE",B24 = "CH",B24 = "NO",B24 = "DK",B24 = "FI"), 1, 0) -> 1 | X24: =W24*I24 -> 5.1 | Y24: =W24*K24 -> 3.1 | Z24: =IF(OR(B24 = "US",B24 = "CA",B24 = "UK",B24 = "NZ",B24 = "AU",B24 = "SG"), 1, 0) -> 0 | AA24: =VLOOKUP(S24,CPI!$A$2:$F$71,6,0) -> 1.47721 | AB24: =U24*AA24 -> 1016.0693 | AC24: =V24*AA24 -> 199.22928 | AD24: Media | AE24: https://www.novinite.com/articles/167648/Subway+Trains+to+Sofia+Airport+Start+Running+at+1+pm+on+April+2
A25: 8194 | B25: BH | C25: Bahrain | D25: Phase 1 | E25: Phase 1 (Red & Blue) | F25: 2018 | G25: 2023 | H25: 1 | I25: 28.6 | J25: =K25/I25 -> 0 | K25: 0 | L25: 0 | M25: 0 | N25: 20 | Q25: 453 | R25: BD | S25: 2019 | T25: =1/0.2 -> 5 | U25: =Q25*T25 -> 2265 | V25: =U25/I25 -> 79.195804 | W25: =IF(OR(B25 = "BG",B25 = "GR",B25 = "IT",B25 = "ES",B25 = "PT",B25 = "TR", B25 = "KR",B25 = "SE",B25 = "CH",B25 = "NO",B25 = "DK",B25 = "FI"), 1, 0) -> 0 | X25: =W25*I25 -> 0 | Y25: =W25*K25 -> 0 | Z25: =IF(OR(B25 = "US",B25 = "CA",B25 = "UK",B25 = "NZ",B25 = "AU",B25 = "SG"), 1, 0) -> 0 | AA25: =VLOOKUP(S25,CPI!$A$2:$F$71,6,0) -> 1.2599479 | AB25: =U25*AA25 -> 2853.782 | AC25: =V25*AA25 -> 99.782587 | AD25: Media | AE25: https://www.urbantransportnews.com/bahrain-to-finalise-109-km-light-metro-rail-bids-in-march-2020/
A26: 8195 | B26: BH | C26: Bahrain | D26: Phase 2 | E26: Phase 2 | F26: 2020 | G26: X | H26: 1 | I26: 72.7 | J26: =K26/I26 -> 0 | K26: 0 | L26: 0 | M26: 0 | Q26: 1500 | R26: BD | S26: 2010 | T26: =1/0.2 -> 5 | U26: =Q26*T26 -> 7500 | V26: =U26/I26 -> 103.16369 | W26: =IF(OR(B26 = "BG",B26 = "GR",B26 = "IT",B26 = "ES",B26 = "PT",B26 = "TR", B26 = "KR",B26 = "SE",B26 = "CH",B26 = "NO",B26 = "DK",B26 = "FI"), 1, 0) -> 0 | X26: =W26*I26 -> 0 | Y26: =W26*K26 -> 0 | Z26: =IF(OR(B26 = "US",B26 = "CA",B26 = "UK",B26 = "NZ",B26 = "AU",B26 = "SG"), 1, 0) -> 0 | AA26: =VLOOKUP(S26,CPI!$A$2:$F$71,6,0) -> 1.47721 | AB26: =U26*AA26 -> 11079.075 | AC26: =V26*AA26 -> 152.39443 | AD26: Media | AE26: http://www.tradearabia.com/news/stn_178416.html
A27: 9754 | B27: BR | C27: Rio de Janeiro | D27: Line 4 | E27: Line 4 | F27: 2010 | G27: 2016 | H27: 0 | I27: 16 | J27: 0.96 | K27: 15.4 | L27: 0 | M27: 0 | N27: 7 | P27: Measured | Q27: 10300 | R27: BRL | S27: 2013 | T27: 0.59 | U27: =Q27*T27 -> 6077 | V27: =U27/I27 -> 379.8125 | W27: =IF(OR(B27 = "BG",B27 = "GR",B27 = "IT",B27 = "ES",B27 = "PT",B27 = "TR", B27 = "KR",B27 = "SE",B27 = "CH",B27 = "NO",B27 = "DK",B27 = "FI"), 1, 0) -> 0 | X27: =W27*I27 -> 0 | Y27: =W27*K27 -> 0 | Z27: =IF(OR(B27 = "US",B27 = "CA",B27 = "UK",B27 = "NZ",B27 = "AU",B27 = "SG"), 1, 0) -> 0 | AA27: =VLOOKUP(S27,CPI!$A$2:$F$71,6,0) -> 1.3827208 | AB27: =U27*AA27 -> 8402.7946 | AC27: =V27*AA27 -> 525.17466 | AD27: Trade | AE27: http://itdpbrasil.org.br/wp-content/uploads/2018/05/ITDP_PP_Linha_4_Maio_2018.pdf
A28: 7344 | B28: BR | C28: Salvador | D28: Lines 1-2 | E28: Lines 1-2 | F28: 2000 | G28: 2017 | H28: 0 | I28: 33 | J28: 0.04 | K28: 1.4 | L28: 10.935 | M28: 20.745 | N28: 20 | P28: Wiki | Q28: 4800 | R28: BRL | S28: 2012 | T28: 0.62 | U28: =Q28*T28 -> 2976 | V28: =U28/I28 -> 90.181818 | W28: =IF(OR(B28 = "BG",B28 = "GR",B28 = "IT",B28 = "ES",B28 = "PT",B28 = "TR", B28 = "KR",B28 = "SE",B28 = "CH",B28 = "NO",B28 = "DK",B28 = "FI"), 1, 0) -> 0 | X28: =W28*I28 -> 0 | Y28: =W28*K28 -> 0 | Z28: =IF(OR(B28 = "US",B28 = "CA",B28 = "UK",B28 = "NZ",B28 = "AU",B28 = "SG"), 1, 0) -> 0 | AA28: =VLOOKUP(S28,CPI!$A$2:$F$71,6,0) -> 1.4029744 | AB28: =U28*AA28 -> 4175.2518 | AC28: =V28*AA28 -> 126.52278 | AD28: Media | AE28: http://patrocinados.estadao.com.br/ccr/salvadors-subway-becomes-a-model-of-success/
A29: 9755 | B29: BR | C29: Salvador | D29: SkyRail Bahia | E29: SkyRail Bahia | F29: 2020 | G29: 2022 | H29: 0 | I29: 23.3 | J29: 0 | K29: 0 | L29: 0 | M29: 0 | N29: 26 | P29: Trade | Q29: 689 | R29: USD | S29: 2021 | T29: 2.3 | U29: =Q29*T29 -> 1584.7 | V29: =U29/I29 -> 68.012876 | W29: =IF(OR(B29 = "BG",B29 = "GR",B29 = "IT",B29 = "ES",B29 = "PT",B29 = "TR", B29 = "KR",B29 = "SE",B29 = "CH",B29 = "NO",B29 = "DK",B29 = "FI"), 1, 0) -> 0 | X29: =W29*I29 -> 0 | Y29: =W29*K29 -> 0 | Z29: =IF(OR(B29 = "US",B29 = "CA",B29 = "UK",B29 = "NZ",B29 = "AU",B29 = "SG"), 1, 0) -> 0 | AA29: =VLOOKUP(S29,CPI!$A$2:$F$71,6,0) -> 1.188746 | AB29: =U29*AA29 -> 1883.8058 | AC29: =V29*AA29 -> 80.850033 | AD29: Trade | AE29: https://www.yicaiglobal.com/news/byd-design-for-usd689-million-brazil-monorail-gets-green-light
A30: 7339 | B30: BR | C30: Sao Paulo | D30: Line 5 | E30: Line 5 extension | F30: 2010 | G30: 2019 | H30: 0 | I30: 12 | J30: 1 | K30: 12 | L30: 0 | M30: 0 | N30: 11 | P30: Wiki | Q30: 6900 | R30: BRL | S30: 2014 | T30: 0.55 | U30: =Q30*T30 -> 3795 | V30: =U30/I30 -> 316.25 | W30: =IF(OR(B30 = "BG",B30 = "GR",B30 = "IT",B30 = "ES",B30 = "PT",B30 = "TR", B30 = "KR",B30 = "SE",B30 = "CH",B30 = "NO",B30 = "DK",B30 = "FI"), 1, 0) -> 0 | X30: =W30*I30 -> 0 | Y30: =W30*K30 -> 0 | Z30: =IF(OR(B30 = "US",B30 = "CA",B30 = "UK",B30 = "NZ",B30 = "AU",B30 = "SG"), 1, 0) -> 0 | AA30: =VLOOKUP(S30,CPI!$A$2:$F$71,6,0) -> 1.3606486 | AB30: =U30*AA30 -> 5163.6613 | AC30: =V30*AA30 -> 430.30511 | AD30: Trade | AE30: https://www.bnamericas.com/en/news/brazil-metro-cost-overruns-top-us9bn1
A31: 9756 | B31: BR | C31: Sao Paulo | D31: Line 17 | E31: Line 17 | F31: 2012 | G31: 2021 | H31: 0 | I31: 7.7 | J31: 0 | K31: 0 | L31: 0 | M31: 0 | N31: 8 | P31: Trade | Q31: 1300 | R31: USD | S31: 2016 | T31: 2.3 | U31: =Q31*T31 -> 2990 | V31: =U31/I31 -> 388.31169 | W31: =IF(OR(B31 = "BG",B31 = "GR",B31 = "IT",B31 = "ES",B31 = "PT",B31 = "TR", B31 = "KR",B31 = "SE",B31 = "CH",B31 = "NO",B31 = "DK",B31 = "FI"), 1, 0) -> 0 | X31: =W31*I31 -> 0 | Y31: =W31*K31 -> 0 | Z31: =IF(OR(B31 = "US",B31 = "CA",B31 = "UK",B31 = "NZ",B31 = "AU",B31 = "SG"), 1, 0) -> 0 | AA31: =VLOOKUP(S31,CPI!$A$2:$F$71,6,0) -> 1.3421046 | AB31: =U31*AA31 -> 4012.8928 | AC31: =V31*AA31 -> 521.15491 | AD31: Trade | AE31: https://www.railjournal.com/in_depth/21-rail-projects-to-watch-in-2021
A32: 7528 | B32: BR | C32: Sao Paulo | D32: Line 6 | E32: Line 6 phase 1 | F32: 2015 | G32: 2023 | H32: 0 | I32: 15.9 | J32: 0.84 | K32: 13.4 | L32: 0 | M32: 0 | N32: 15 | P32: Trade | Q32: 9600 | R32: BRL | S32: 2020 | T32: 0.44 | U32: =Q32*T32 -> 4224 | V32: =U32/I32 -> 265.66038 | W32: =IF(OR(B32 = "BG",B32 = "GR",B32 = "IT",B32 = "ES",B32 = "PT",B32 = "TR", B32 = "KR",B32 = "SE",B32 = "CH",B32 = "NO",B32 = "DK",B32 = "FI"), 1, 0) -> 0 | X32: =W32*I32 -> 0 | Y32: =W32*K32 -> 0 | Z32: =IF(OR(B32 = "US",B32 = "CA",B32 = "UK",B32 = "NZ",B32 = "AU",B32 = "SG"), 1, 0) -> 0 | AA32: =VLOOKUP(S32,CPI!$A$2:$F$71,6,0) -> 1.2445935 | AB32: =U32*AA32 -> 5257.1631 | AC32: =V32*AA32 -> 330.63919 | AD32: Trade | AE32: https://www.railjournal.com/passenger/metros/revival-of-sao-paulo-metro-line-6-orange-project-a-step-closer/
A33: 9761 | B33: CA | C33: Calgary | D33: Green Line | E33: Green Line stage 1 | F33: 2021 | G33: 2027 | H33: 0 | I33: 20 | J33: 0.2 | K33: 4 | L33: 0 | M33: 0 | N33: 15 | P33: Wiki | Q33: 5500 | R33: CAD | S33: 2024 | T33: 0.84 | U33: =Q33*T33 -> 4620 | V33: =U33/I33 -> 231 | W33: =IF(OR(B33 = "BG",B33 = "GR",B33 = "IT",B33 = "ES",B33 = "PT",B33 = "TR", B33 = "KR",B33 = "SE",B33 = "CH",B33 = "NO",B33 = "DK",B33 = "FI"), 1, 0) -> 0 | X33: =W33*I33 -> 0 | Y33: =W33*K33 -> 0 | Z33: =IF(OR(B33 = "US",B33 = "CA",B33 = "UK",B33 = "NZ",B33 = "AU",B33 = "SG"), 1, 0) -> 1 | AA33: =VLOOKUP(S33,CPI!$A$2:$F$71,6,0) -> 1 | AB33: =U33*AA33 -> 4620 | AC33: =V33*AA33 -> 231 | AD33: Media | AE33: https://globalnews.ca/news/7527443/green-line-lrt-calgary-alberta-government/
A34: 7106 | B34: CA | C34: Calgary | D34: Blue Line Extension | E34: Northeast | F34: 2027 | G34: ~ | H34: 0 | I34: 1 | J34: 0 | K34: 0 | L34: 0 | M34: 1 | N34: 1 | O34: 40 | P34: Plan | Q34: 160.6 | R34: CAD | S34: 2027 | T34: 1 | U34: =Q34*T34 -> 160.6 | V34: =U34/I34 -> 160.6 | W34: =IF(OR(B34 = "BG",B34 = "GR",B34 = "IT",B34 = "ES",B34 = "PT",B34 = "TR", B34 = "KR",B34 = "SE",B34 = "CH",B34 = "NO",B34 = "DK",B34 = "FI"), 1, 0) -> 0 | X34: =W34*I34 -> 0 | Y34: =W34*K34 -> 0 | Z34: 1 | AA34: =VLOOKUP(S34,CPI!$A$2:$F$71,6,0) -> 1 | AB34: =U34*AA34 -> 160.6 | AC34: =V34*AA34 -> 160.6
B35: CA | C35: Edmonton | D35: Valley Line Southeast | E35: Southeast | F35: 2016 | G35: 2023 | H35: 0 | I35: 13.1 | J35: 0.03 | K35: 0.4 | N35: 12 | O35: 125 | P35: Wiki | Q35: 1800 | R35: CAD | S35: 2019 | T35: 0.802 | U35: =Q35*T35 -> 1443.6 | V35: =U35/I35 -> 110.19847 | W35: =IF(OR(B35 = "BG",B35 = "GR",B35 = "IT",B35 = "ES",B35 = "PT",B35 = "TR", B35 = "KR",B35 = "SE",B35 = "CH",B35 = "NO",B35 = "DK",B35 = "FI"), 1, 0) -> 0 | X35: =W35*I35 -> 0 | Y35: =W35*K35 -> 0 | Z35: =IF(OR(B35 = "US",B35 = "CA",B35 = "UK",B35 = "NZ",B35 = "AU",B35 = "SG"), 1, 0) -> 1 | AA35: =VLOOKUP(S35,CPI!$A$2:$F$71,6,0) -> 1.2599479 | AB35: =U35*AA35 -> 1818.8608 | AC35: =V35*AA35 -> 138.84433 | AD35: Media | AE35: https://edmontonjournal.com/news/local-news/long-delayed-1-8-billion-valley-line-lrt-stymied-yet-again
A36: 7104 | B36: CA | C36: Edmonton | D36: Metro Line Extension | E36: Northwest Phase 1 | F36: 2020 | G36: 2024 | H36: 0 | I36: 1.6 | J36: 0 | K36: 0 | L36: 0 | M36: 1.6 | N36: 2 | O36: 125 | P36: Plan | Q36: 291 | R36: CAD | S36: 2020 | T36: 0.81 | U36: =Q36*T36 -> 235.71 | V36: =U36/I36 -> 147.31875 | Z36: 1 | AA36: =VLOOKUP(S36,CPI!$A$2:$F$71,6,0) -> 1.2445935 | AB36: =U36*AA36 -> 293.36314 | AC36: =V36*AA36 -> 183.35197 | AE36: https://www.edmonton.ca/projects_plans/transit/nw-lrt https://tam-america.com/article/edmonton-metro-northwest-lrt-extension-phase-completed-on-budget-before-time#:~:text=Phase%201%20construction%20was%20originally,million%20(US%24215%20million).
A37: 7103 | B37: CA | C37: Edmonton | D37: Valley Line Extension | E37: West | F37: 2022 | G37: 2028 | H37: 0 | I37: 14 | J37: 0 | K37: 0 | L37: 2.1 | M37: =14-2.1 -> 11.9 | N37: 14 | O37: 125 | P37: Plan | Q37: 2700 | R37: CAD | S37: 2022 | T37: 0.88 | U37: =Q37*T37 -> 2376 | V37: =U37/I37 -> 169.71429 | W37: 0 | Z37: 1 | AA37: =VLOOKUP(S37,CPI!$A$2:$F$71,6,0) -> 1.1006629 | AB37: =U37*AA37 -> 2615.175 | AC37: =V37*AA37 -> 186.79822 | AD37: Media | AE37: https://majorprojects.alberta.ca/details/Valley-Line-West-LRT/3692 https://www.operis.com/case-study/edmonton-valley-line-west/
A38: 7116 | B38: CA | C38: Hamilton | D38: Hamilton LRT | E38: Phase 1 | F38: 2025 | G38: 2029 | H38: 0 | I38: 14 | J38: 0 | K38: 0 | L38: 0 | M38: 14 | N38: 17 | O38: 50 | P38: Plan | Q38: 3400 | R38: CAD | S38: 2025 | T38: 1 | U38: =Q38*T38 -> 3400 | V38: =U38/I38 -> 242.85714 | AA38: =VLOOKUP(S38,CPI!$A$2:$F$71,6,0) -> 1 | AB38: =U38*AA38 -> 3400 | AC38: =V38*AA38 -> 242.85714 | AD38: Media | AE38: https://www.metrolinx.com/en/projects-and-programs/hamilton-lrt https://canada.constructconnect.com/dcn/news/infrastructure/2024/11/request-for-qualifications-issued-for-hamilton-lrt-project
A39: 7114 | B39: CA | C39: Mississauga | D39: Hazel McCallion LRT | E39: Phase 1 | F39: 2020 | G39: 2027 | H39: 0 | I39: 18 | J39: =(1/19)% -> 0.00052631579 | K39: 1 | M39: 18 | N39: 19 | O39: 50 | P39: Plan | Q39: 4700 | R39: CAD | S39: 2020 | T39: 0.84 | U39: =Q39*T39 -> 3948 | V39: =U39/I39 -> 219.33333 | AA39: =VLOOKUP(S39,CPI!$A$2:$F$71,6,0) -> 1.2445935 | AB39: =U39*AA39 -> 4913.6553 | AC39: =V39*AA39 -> 272.98085 | AD39: Media | AE39: https://www.metrolinx.com/en/projects-and-programs/hazel-mccallion-lrt/faqs
A40: 7401 | B40: CA | C40: Montreal | D40: Laval extension | E40: Laval extension | F40: 2001 | G40: 2007 | H40: 0 | I40: 5.2 | J40: 1 | K40: 5.2 | L40: 0 | M40: 0 | N40: 3 | P40: Wiki | Q40: 745 | R40: CAD | S40: 2004 | T40: 0.81 | U40: =Q40*T40 -> 603.45 | V40: =U40/I40 -> 116.04808 | W40: =IF(OR(B40 = "BG",B40 = "GR",B40 = "IT",B40 = "ES",B40 = "PT",B40 = "TR", B40 = "KR",B40 = "SE",B40 = "CH",B40 = "NO",B40 = "DK",B40 = "FI"), 1, 0) -> 0 | X40: =W40*I40 -> 0 | Y40: =W40*K40 -> 0 | Z40: =IF(OR(B40 = "US",B40 = "CA",B40 = "UK",B40 = "NZ",B40 = "AU",B40 = "SG"), 1, 0) -> 1 | AA40: =VLOOKUP(S40,CPI!$A$2:$F$71,6,0) -> 1.7052118 | AB40: =U40*AA40 -> 1029.01 | AC40: =V40*AA40 -> 197.88654 | AD40: Media | AE40: https://montrealgazette.com/news/local-news/the-sleepy-success-story-of-the-laval-metro-extension
A41: 7146 | B41: CA | C41: Montreal | D41: Blue Line | E41: Blue Line | F41: 2020 | G41: 2026 | H41: 0 | I41: 5.8 | J41: 1 | K41: 5.8 | L41: 0 | M41: 0 | N41: 5 | P41: Media | Q41: 7600 | R41: CAD | S41: 2018 | T41: 0.84 | U41: =Q41*T41 -> 6384 | V41: =U41/I41 -> 1100.6897 | W41: =IF(OR(B41 = "BG",B41 = "GR",B41 = "IT",B41 = "ES",B41 = "PT",B41 = "TR", B41 = "KR",B41 = "SE",B41 = "CH",B41 = "NO",B41 = "DK",B41 = "FI"), 1, 0) -> 0 | X41: =W41*I41 -> 0 | Y41: =W41*K41 -> 0 | Z41: =IF(OR(B41 = "US",B41 = "CA",B41 = "UK",B41 = "NZ",B41 = "AU",B41 = "SG"), 1, 0) -> 1 | AA41: =VLOOKUP(S41,CPI!$A$2:$F$71,6,0) -> 1.2827779 | AB41: =U41*AA41 -> 8189.2539 | AC41: =V41*AA41 -> 1411.9403 | AD41: Media | AE41: https://montrealgazette.com/news/local-news/montreal-metro-green-light-for-blue-line-extension https://www.cbc.ca/news/canada/montreal/blue-line-extension-delayed-1.7303767
A42: 7130 | B42: CA | C42: Montreal | D42: PSE | E42: Phase 1 | F42: 2025 | G42: 2033 | H42: 0 | I42: 31 | J42: 0 | K42: 0 | L42: 0 | M42: 31 | N42: 36/22 | P42: Plan | Q42: 19000 | R42: CAD | S42: 2025 | T42: 1 | U42: 19000 | V42: =U42/I42 -> 612.90323 | Z42: 0 | AA42: =VLOOKUP(S42,CPI!$A$2:$F$71,6,0) -> 1 | AB42: =U42*AA42 -> 19000 | AC42: =V42*AA42 -> 612.90323 | AD42: Media | AE42: https://www.cbc.ca/news/canada/montreal/public-transit-project-announcement-eastern-montreal-1.7475018 https://www.artm.quebec/wp-content/uploads/2024/05/RP_PSE_AC_VFinale_2024-05-28.pdf
A43: 7125 | B43: CA | C43: Montreal | D43: REM | E43: Current Project Scope | F43: 2018 | G43: 2027 | H43: 0 | I43: 67 | J43: =10.5/67 -> 0.15671642 | K43: 10.5 | L43: 16.3 | M43: 36.7 | N43: 24 | O43: 26 | P43: Plan | Q43: 9400 | R43: CAD | S43: 2018 | T43: 0.84 | U43: =Q43*T43 -> 7896 | V43: =U43/I43 -> 117.85075 | W43: 0 | X43: =W43*I43 -> 0 | Y43: =X43*J43 -> 0 | Z43: 1 | AA43: =VLOOKUP(S43,CPI!$A$2:$F$71,6,0) -> 1.2827779 | AB43: =U43*AA43 -> 10128.814 | AC43: =V43*AA43 -> 151.17633 | AD43: Media | AE43: https://scfp.ca/sites/default/files/ppp201700191_ppp_canada_rem_01_01_2016_part2-opt_0.pdf https://montreal.citynews.ca/2024/11/20/quebec-educational-gap-indigenous-students-auditor-general-report/
A44: 7117 | B44: CA | C44: Ottawa | D44: Confederation | E44: Confederation | F44: 2013 | G44: 2019 | H44: 0 | I44: 12.5 | J44: 0.2 | K44: 2.5 | L44: 0.84 | M44: 9.16 | N44: 13 | O44: 90/120 | P44: Trade | Q44: 2100 | R44: CAD | S44: 2016 | T44: 0.83 | U44: =Q44*T44 -> 1743 | V44: =U44/I44 -> 139.44 | W44: =IF(OR(B44 = "BG",B44 = "GR",B44 = "IT",B44 = "ES",B44 = "PT",B44 = "TR", B44 = "KR",B44 = "SE",B44 = "CH",B44 = "NO",B44 = "DK",B44 = "FI"), 1, 0) -> 0 | X44: =W44*I44 -> 0 | Y44: =W44*K44 -> 0 | Z44: =IF(OR(B44 = "US",B44 = "CA",B44 = "UK",B44 = "NZ",B44 = "AU",B44 = "SG"), 1, 0) -> 1 | AA44: =VLOOKUP(S44,CPI!$A$2:$F$71,6,0) -> 1.3421046 | AB44: =U44*AA44 -> 2339.2883 | AC44: =V44*AA44 -> 187.14307 | AD44: Trade | AE44: https://www.aecom.com/projects/ottawa-light-rail/
A45: 7118 | B45: CA | C45: Ottawa | D45: Confederation | E45: East West Extensions | F45: 2019 | G45: 2025 | H45: 0 | I45: 28 | J45: =(3.4/28) -> 0.12142857 | K45: 3.4 | L45: 0 | M45: 12 | N45: 17 | O45: 90/120 | P45: Plan | Q45: 2600 | R45: CAD | S45: 2019 | T45: 0.802 | U45: =Q45*T45 -> 2085.2 | V45: =U45/I45 -> 74.471429 | Z45: 1 | AA45: =VLOOKUP(S45,CPI!$A$2:$F$71,6,0) -> 1.2599479 | AB45: =U45*AA45 -> 2627.2434 | AC45: =V45*AA45 -> 93.83012 | AD45: Trade | AE45: https://www.kiewit.com/projects/ottawa-lrt-stage-2/ https://pub-ottawa.escribemeetings.com/filestream.ashx?documentid=58389 https://delveunderground.com/projects/ottawa-light-rail-transit-stages-1-and-2
...

Sheet Sheet3
D7: 3928.5714
D8: 1792.4528
D9: 888.53333
D10: 292.5
D11: 854.76086
D12: 287.5
D13: 394.90244
D14: 535.71429
D15: 276.26
D16: 99.824
D17: 121.08636
D18: 391.72291
... D29: 160.5
D30: =QUARTILE(D7:D29,1) -> 207.97179
D31: =QUARTILE(D7:D30,3) -> 582.20759
D33: =MEDIAN(D7:D29) -> 287.5 | E33: =PERCENTILE(D7:D29,0.28) -> 228.583

Sheet 2_28_2026
A1: Country | B1: City | C1: Line | D1: Phase | E1: Start year | F1: End year | G1: RR? | H1: Length | I1: TunnelPer | J1: Tunnel | K1: Elevated | L1: Atgrade | M1: Stations | N1: Platform Length (Meters) | O1: Source1 | P1: Cost | Q1: Currency | R1: Year | S1: PPP rate | T1: Real cost | U1: Cost/km (Millions) | V1: Cheap? | W1: Clength | X1: Ctunnel | Y1: Anglo? | Z1: Inflation Index | AA1: Real cost (2025 dollars) | AB1: Cost/km (2025 dollars) | AC1: Source2 | AD1: Reference
A2: AE | B2: Dubai | C2: Phase 1 | D2: Phase 1 - Red Line | E2: 2005 | F2: 2010 | G2: 0 | H2: 35 | I2: =J2/H2 -> 0.13428571 | J2: 4.7 | K2: 0 | L2: 0 | M2: 29 | O2: Trade | P2: 4200 | Q2: USD | R2: 2005 | S2: 1.8 | T2: =P2*S2 -> 7560 | U2: =T2/H2 -> 216 | V2: =IF(OR(A2 = "BG",A2 = "GR",A2 = "IT",A2 = "ES",A2 = "PT",A2 = "TR", A2 = "KR",A2 = "SE",A2 = "CH",A2 = "NO",A2 = "DK",A2 = "FI"), 1, 0) -> 0 | W2: =V2*H2 -> 0 | X2: =V2*J2 -> 0 | Y2: =IF(OR(A2 = "US",A2 = "CA",A2 = "UK",A2 = "NZ",A2 = "AU",A2 = "SG"), 1, 0) -> 0 | Z2: =VLOOKUP(R2,CPI!$A$2:$F$71,6,0) -> 1.6493318 | AA2: =T2*Z2 -> 12468.948 | AB2: =U2*Z2 -> 356.25567
A3: AE | B3: Dubai | C3: Phase 2 | D3: Phase 2 - Green Line | E3: 2006 | F3: 2010 | G3: 0 | H3: 22.5 | I3: =J3/H3 -> 0.35111111 | J3: 7.9 | K3: 0 | L3: 0 | M3: 20 | P3: 3600 | Q3: USD | R3: 2006 | S3: 1.9 | T3: =P3*S3 -> 6840 | U3: =T3/H3 -> 304 | V3: =IF(OR(A3 = "BG",A3 = "GR",A3 = "IT",A3 = "ES",A3 = "PT",A3 = "TR", A3 = "KR",A3 = "SE",A3 = "CH",A3 = "NO",A3 = "DK",A3 = "FI"), 1, 0) -> 0 | W3: =V3*H3 -> 0 | X3: =V3*J3 -> 0 | Y3: =IF(OR(A3 = "US",A3 = "CA",A3 = "UK",A3 = "NZ",A3 = "AU",A3 = "SG"), 1, 0) -> 0 | Z3: =VLOOKUP(R3,CPI!$A$2:$F$71,6,0) -> 1.5977902 | AA3: =T3*Z3 -> 10928.885 | AB3: =U3*Z3 -> 485.72821
A4: AE | B4: Dubai | C4: Red Line | D4: Phase 3 (Red Line Extension/Route 2020) | E4: 2016 | F4: 2020 | G4: 0 | H4: 15 | I4: =J4/H4 -> 0.21333333 | J4: 3.2 | K4: 0 | L4: 0 | M4: 7 | O4: Trade | P4: 2900 | Q4: USD | R4: 2016 | S4: 1.9 | T4: =P4*S4 -> 5510 | U4: =T4/H4 -> 367.33333 | V4: =IF(OR(A4 = "BG",A4 = "GR",A4 = "IT",A4 = "ES",A4 = "PT",A4 = "TR", A4 = "KR",A4 = "SE",A4 = "CH",A4 = "NO",A4 = "DK",A4 = "FI"), 1, 0) -> 0 | W4: =V4*H4 -> 0 | X4: =V4*J4 -> 0 | Y4: =IF(OR(A4 = "US",A4 = "CA",A4 = "UK",A4 = "NZ",A4 = "AU",A4 = "SG"), 1, 0) -> 0 | Z4: =VLOOKUP(R4,CPI!$A$2:$F$71,6,0) -> 1.3421046 | AA4: =T4*Z4 -> 7394.9964 | AB4: =U4*Z4 -> 492.99976 | AC4: Media | AD4: https://www.railway-technology.com/projects/route-2020-dubai/
A5: AR | B5: Buenos Aires | C5: RER | D5: RER | E5: 2020 | F5: 2026 | G5: 1 | H5: 20 | I5: 1 | J5: 20 | K5: 0 | L5: 0 | M5: 4 | O5: Media | P5: 2300 | Q5: USD | R5: 2023 | S5: 2.02 | T5: =P5*S5 -> 4646 | U5: =T5/H5 -> 232.3 | V5: =IF(OR(A5 = "BG",A5 = "GR",A5 = "IT",A5 = "ES",A5 = "PT",A5 = "TR", A5 = "KR",A5 = "SE",A5 = "CH",A5 = "NO",A5 = "DK",A5 = "FI"), 1, 0) -> 0 | W5: =V5*H5 -> 0 | X5: =V5*J5 -> 0 | Y5: =IF(OR(A5 = "US",A5 = "CA",A5 = "UK",A5 = "NZ",A5 = "AU",A5 = "SG"), 1, 0) -> 0 | Z5: =VLOOKUP(R5,CPI!$A$2:$F$71,6,0) -> 1.057146 | AA5: =T5*Z5 -> 4911.5003 | AB5: =U5*Z5 -> 245.57502 | AC5: Media | AD5: https://tn.com.ar/economia/el-gobierno-relanzo-el-rer-el-proyecto-para-conectar-los-trenes-del-area-metropolitana_856411
A6: AT | B6: Vienna | C6: va | D6: Lainz Tunnel | E6: 1999 | F6: 2012 | G6: 1 | H6: 12.8 | I6: 1 | J6: 12.8 | K6: 0 | L6: 0 | M6: 0 | O6: Media | P6: 1300 | Q6: EUR | R6: 2005 | S6: 1.25 | T6: =P6*S6 -> 1625 | U6: =T6/H6 -> 126.95312 | V6: =IF(OR(A6 = "BG",A6 = "GR",A6 = "IT",A6 = "ES",A6 = "PT",A6 = "TR", A6 = "KR",A6 = "SE",A6 = "CH",A6 = "NO",A6 = "DK",A6 = "FI"), 1, 0) -> 0 | W6: =V6*H6 -> 0 | X6: =V6*J6 -> 0 | Y6: =IF(OR(A6 = "US",A6 = "CA",A6 = "UK",A6 = "NZ",A6 = "AU",A6 = "SG"), 1, 0) -> 0 | Z6: =VLOOKUP(R6,CPI!$A$2:$F$71,6,0) -> 1.6493318 | AA6: =T6*Z6 -> 2680.1642 | AB6: =U6*Z6 -> 209.38783 | AC6: Media | AD6: https://wien.orf.at/v2/news/stories/2537074/
A7: AT | B7: Vienna | C7: Line 2 | D7: Line 2 extension | E7: 2010 | F7: 2013 | G7: 0 | H7: 4.2 | I7: 0 | J7: 0 | K7: 2.63 | L7: 1.57 | M7: 3 | O7: Media | P7: 320 | Q7: EUR | R7: 2012 | S7: 1.3 | T7: =P7*S7 -> 416 | U7: =T7/H7 -> 99.047619 | V7: =IF(OR(A7 = "BG",A7 = "GR",A7 = "IT",A7 = "ES",A7 = "PT",A7 = "TR", A7 = "KR",A7 = "SE",A7 = "CH",A7 = "NO",A7 = "DK",A7 = "FI"), 1, 0) -> 0 | W7: =V7*H7 -> 0 | X7: =V7*J7 -> 0 | Y7: =IF(OR(A7 = "US",A7 = "CA",A7 = "UK",A7 = "NZ",A7 = "AU",A7 = "SG"), 1, 0) -> 0 | Z7: =VLOOKUP(R7,CPI!$A$2:$F$71,6,0) -> 1.4029744 | AA7: =T7*Z7 -> 583.63734 | AB7: =U7*Z7 -> 138.96127 | AC7: Media | AD7: https://wien.orf.at/news/stories/2607445/
A8: AT | B8: Vienna | C8: Line 1 | D8: Line 1 extension | E8: 2012 | F8: 2017 | G8: 0 | H8: 4.7 | I8: 0.57 | J8: 2.7 | K8: 0.06 | L8: 2.008 | M8: 5 | O8: Measured | P8: 600 | Q8: EUR | R8: 2015 | S8: 1.3 | T8: =P8*S8 -> 780 | U8: =T8/H8 -> 165.95745 | V8: =IF(OR(A8 = "BG",A8 = "GR",A8 = "IT",A8 = "ES",A8 = "PT",A8 = "TR", A8 = "KR",A8 = "SE",A8 = "CH",A8 = "NO",A8 = "DK",A8 = "FI"), 1, 0) -> 0 | W8: =V8*H8 -> 0 | X8: =V8*J8 -> 0 | Y8: =IF(OR(A8 = "US",A8 = "CA",A8 = "UK",A8 = "NZ",A8 = "AU",A8 = "SG"), 1, 0) -> 0 | Z8: =VLOOKUP(R8,CPI!$A$2:$F$71,6,0) -> 1.3590354 | AA8: =T8*Z8 -> 1060.0476 | AB8: =U8*Z8 -> 225.54205 | AC8: Plan | AD8: https://www.wien.gv.at/stadtentwicklung/projekte/verkehrsplanung/u-bahn/u1-oberlaa.html
A9: AT | B9: Vienna | C9: U2/U5 cross | D9: U2/U5 cross | E9: 2019 | F9: 2029 | G9: 0 | H9: 9 | I9: 1 | J9: 9 | K9: 0 | L9: 0 | M9: 11 | O9: Plan | P9: 2200 | Q9: EUR | R9: 2023 | S9: 1.3 | T9: =P9*S9 -> 2860 | U9: =T9/H9 -> 317.77778 | V9: =IF(OR(A9 = "BG",A9 = "GR",A9 = "IT",A9 = "ES",A9 = "PT",A9 = "TR", A9 = "KR",A9 = "SE",A9 = "CH",A9 = "NO",A9 = "DK",A9 = "FI"), 1, 0) -> 0 | W9: =V9*H9 -> 0 | X9: =V9*J9 -> 0 | Y9: =IF(OR(A9 = "US",A9 = "CA",A9 = "UK",A9 = "NZ",A9 = "AU",A9 = "SG"), 1, 0) -> 0 | Z9: =VLOOKUP(R9,CPI!$A$2:$F$71,6,0) -> 1.057146 | AA9: =T9*Z9 -> 3023.4376 | AB9: =U9*Z9 -> 335.93751 | AC9: Media | AD9: https://wien.orf.at/news/stories/2940360/
A10: AU | B10: Melbourne | C10: Metro Tunnel | D10: Metro Tunnel | E10: 2018 | F10: 2025 | G10: 0 | H10: 9 | I10: 1 | J10: 9 | K10: 0 | L10: 0 | M10: 5 | O10: Plan | P10: 12584.4 | Q10: AUD | R10: 2021 | S10: 0.69 | T10: =P10*S10 -> 8683.236 | U10: =T10/H10 -> 964.804 | V10: =IF(OR(A10 = "BG",A10 = "GR",A10 = "IT",A10 = "ES",A10 = "PT",A10 = "TR", A10 = "KR",A10 = "SE",A10 = "CH",A10 = "NO",A10 = "DK",A10 = "FI"), 1, 0) -> 0 | W10: =V10*H10 -> 0 | X10: =V10*J10 -> 0 | Y10: =IF(OR(A10 = "US",A10 = "CA",A10 = "UK",A10 = "NZ",A10 = "AU",A10 = "SG"), 1, 0) -> 1 | Z10: =VLOOKUP(R10,CPI!$A$2:$F$71,6,0) -> 1.188746 | AA10: =T10*Z10 -> 10322.162 | AB10: =U10*Z10 -> 1146.9069 | AC10: Plan | AD10: https://www.audit.vic.gov.au/report/melbourne-metro-tunnel-project-phase-2-main-works?section=
A11: AU | B11: Perth | C11: Forrestfield-Airport Link | D11: Forrestfield-Airport Link | E11: 2016 | F11: 2021 | G11: 1 | H11: 8.5 | I11: 1 | J11: 8.5 | K11: 0 | L11: 0 | M11: 3 | O11: Plan | P11: 1860 | Q11: AUD | R11: 2018 | S11: 0.69 | T11: =P11*S11 -> 1283.4 | U11: =T11/H11 -> 150.98824 | V11: =IF(OR(A11 = "BG",A11 = "GR",A11 = "IT",A11 = "ES",A11 = "PT",A11 = "TR", A11 = "KR",A11 = "SE",A11 = "CH",A11 = "NO",A11 = "DK",A11 = "FI"), 1, 0) -> 0 | W11: =V11*H11 -> 0 | X11: =V11*J11 -> 0 | Y11: =IF(OR(A11 = "US",A11 = "CA",A11 = "UK",A11 = "NZ",A11 = "AU",A11 = "SG"), 1, 0) -> 1 | Z11: =VLOOKUP(R11,CPI!$A$2:$F$71,6,0) -> 1.2827779 | AA11: =T11*Z11 -> 1646.3171 | AB11: =U11*Z11 -> 193.68437 | AC11: Plan | AD11: https://www.forrestfieldairportlink.wa.gov.au/Portals/14/Project%20Overview%20Fact%20Sheet%20-%20Dec18%20WEB.pdf
A12: AU | B12: Sydney | C12: Metro NW | D12: Metro NW | E12: 2013 | F12: 2019 | G12: 0 | H12: 36 | I12: 0.42 | J12: 15.1 | K12: 0 | L12: 0 | M12: 13 | O12: Wiki | P12: 7800 | Q12: AUD | R12: 2016 | S12: 0.69 | T12: =P12*S12 -> 5382 | U12: =T12/H12 -> 149.5 | V12: =IF(OR(A12 = "BG",A12 = "GR",A12 = "IT",A12 = "ES",A12 = "PT",A12 = "TR", A12 = "KR",A12 = "SE",A12 = "CH",A12 = "NO",A12 = "DK",A12 = "FI"), 1, 0) -> 0 | W12: =V12*H12 -> 0 | X12: =V12*J12 -> 0 | Y12: =IF(OR(A12 = "US",A12 = "CA",A12 = "UK",A12 = "NZ",A12 = "AU",A12 = "SG"), 1, 0) -> 1 | Z12: =VLOOKUP(R12,CPI!$A$2:$F$71,6,0) -> 1.3421046 | AA12: =T12*Z12 -> 7223.207 | AB12: =U12*Z12 -> 200.64464 | AC12: Plan | AD12: https://www.transport.nsw.gov.au/news-and-events/media-releases/sydney-metro-northwest-under-budget
A13: AU | B13: Sydney | C13: Metro City & SW | D13: Metro City & SW | E13: 2017 | F13: 2024 | G13: 0 | H13: 30 | I13: 0.51 | J13: 15.3 | K13: 0 | L13: 0 | M13: 7 | O13: Wiki | P13: 15500 | Q13: AUD | R13: 2021 | S13: 0.69 | T13: =P13*S13 -> 10695 | U13: =T13/H13 -> 356.5 | V13: =IF(OR(A13 = "BG",A13 = "GR",A13 = "IT",A13 = "ES",A13 = "PT",A13 = "TR", A13 = "KR",A13 = "SE",A13 = "CH",A13 = "NO",A13 = "DK",A13 = "FI"), 1, 0) -> 0 | W13: =V13*H13 -> 0 | X13: =V13*J13 -> 0 | Y13: =IF(OR(A13 = "US",A13 = "CA",A13 = "UK",A13 = "NZ",A13 = "AU",A13 = "SG"), 1, 0) -> 1 | Z13: =VLOOKUP(R13,CPI!$A$2:$F$71,6,0) -> 1.188746 | AA13: =T13*Z13 -> 12713.638 | AB13: =U13*Z13 -> 423.78794 | AC13: Media | AD13: https://www.abc.net.au/news/2020-02-21/nsw-government-confirms-three-billion-metro-budget-blowout/11986968
A14: BD | B14: Dhaka | C14: Line 6 | D14: Line 6 | E14: 2015 | F14: 2022 | G14: 0 | H14: 21.3 | I14: 0 | J14: 0 | K14: 0 | L14: 0 | M14: 16 | O14: Media | P14: 334720 | Q14: BDT | R14: 2019 | S14: 0.032 | T14: =P14*S14 -> 10711.04 | U14: =T14/H14 -> 502.86573 | V14: =IF(OR(A14 = "BG",A14 = "GR",A14 = "IT",A14 = "ES",A14 = "PT",A14 = "TR", A14 = "KR",A14 = "SE",A14 = "CH",A14 = "NO",A14 = "DK",A14 = "FI"), 1, 0) -> 0 | W14: =V14*H14 -> 0 | X14: =V14*J14 -> 0 | Y14: =IF(OR(A14 = "US",A14 = "CA",A14 = "UK",A14 = "NZ",A14 = "AU",A14 = "SG"), 1, 0) -> 0 | Z14: =VLOOKUP(R14,CPI!$A$2:$F$71,6,0) -> 1.2599479 | AA14: =T14*Z14 -> 13495.352 | AB14: =U14*Z14 -> 633.58462 | AC14: Media | AD14: https://www.thedailystar.net/news/bangladesh/transport/news/metro-now-set-cost-50pc-more-3072816
A15: BD | B15: Dhaka | C15: Line 1 | D15: Line 1 | E15: 2020 | F15: 2026 | G15: 0 | H15: 31.2 | I15: 0.64 | J15: 19.9 | K15: 0 | L15: 0 | M15: 19 | O15: Media | P15: 525610 | Q15: BDT | R15: 2023 | S15: 0.032 | T15: =P15*S15 -> 16819.52 | U15: =T15/H15 -> 539.08718 | V15: =IF(OR(A15 = "BG",A15 = "GR",A15 = "IT",A15 = "ES",A15 = "PT",A15 = "TR", A15 = "KR",A15 = "SE",A15 = "CH",A15 = "NO",A15 = "DK",A15 = "FI"), 1, 0) -> 0 | W15: =V15*H15 -> 0 | X15: =V15*J15 -> 0 | Y15: =IF(OR(A15 = "US",A15 = "CA",A15 = "UK",A15 = "NZ",A15 = "AU",A15 = "SG"), 1, 0) -> 0 | Z15: =VLOOKUP(R15,CPI!$A$2:$F$71,6,0) -> 1.057146 | AA15: =T15*Z15 -> 17780.688 | AB15: =U15*Z15 -> 569.89385 | AC15: Media | AD15: https://bdnews24.com/economy/2019/10/15/govt-approves-two-more-metro-rail-projects-worth-tk-938bn
A16: BD | B16: Dhaka | C16: Line 5 | D16: Line 5 | E16: 2020 | F16: 2028 | G16: 0 | H16: 19.6 | I16: 0.7 | J16: 14 | K16: 0 | L16: 0 | M16: 14 | O16: Media | P16: 412380 | Q16: BDT | R16: 2024 | S16: 0.032 | T16: =P16*S16 -> 13196.16 | U16: =T16/H16 -> 673.27347 | V16: =IF(OR(A16 = "BG",A16 = "GR",A16 = "IT",A16 = "ES",A16 = "PT",A16 = "TR", A16 = "KR",A16 = "SE",A16 = "CH",A16 = "NO",A16 = "DK",A16 = "FI"), 1, 0) -> 0 | W16: =V16*H16 -> 0 | X16: =V16*J16 -> 0 | Y16: =IF(OR(A16 = "US",A16 = "CA",A16 = "UK",A16 = "NZ",A16 = "AU",A16 = "SG"), 1, 0) -> 0 | Z16: =VLOOKUP(R16,CPI!$A$2:$F$71,6,0) -> 1 | AA16: =T16*Z16 -> 13196.16 | AB16: =U16*Z16 -> 673.27347 | AC16: Media | AD16: https://bdnews24.com/economy/2019/10/15/govt-approves-two-more-metro-rail-projects-worth-tk-938bn
... A22: BG | B22: Sofia | C22: Line 3 | D22: Line 3 extension (Third Stage) | E22: 2021 | F22: 2026 | G22: 0 | H22: 3.1 | I22: 1 | J22: 3.1 | K22: 0 | L22: 0 | M22: 4 | O22: Plan | P22: 112.5 | Q22: EUR | R22: 2021 | S22: 3.32 | T22: =P22*S22 -> 373.5 | U22: =T22/H22 -> 120.48387 | V22: =IF(OR(A22 = "BG",A22 = "GR",A22 = "IT",A22 = "ES",A22 = "PT",A22 = "TR", A22 = "KR",A22 = "SE",A22 = "CH",A22 = "NO",A22 = "DK",A22 = "FI"), 1, 0) -> 1 | W22: =V22*H22 -> 3.1 | X22: =V22*J22 -> 3.1 | Y22: =IF(OR(A22 = "US",A22 = "CA",A22 = "UK",A22 = "NZ",A22 = "AU",A22 = "SG"), 1, 0) -> 0 | Z22: =VLOOKUP(R22,CPI!$A$2:$F$71,6,0) -> 1.188746 | AA22: =T22*Z22 -> 443.99663 | AB22: =U22*Z22 -> 143.22472 | AC22: Trade | AD22: https://seenews.com/news/sofia-opens-1125-mln-euro-tender-for-subway-expansion-681553
A23: BG | B23: Sofia | C23: Line 1 | D23: Line 1 northern | E23: 2009 | F23: cond | G23: 0 | H23: 5.1 | I23: 0.6 | J23: 3.1 | K23: 0 | L23: 0 | M23: 4 | O23: Measured | P23: 407 | Q23: BGN | R23: 2010 | S23: 1.69 | T23: =P23*S23 -> 687.83 | U23: =T23/H23 -> 134.86863 | V23: =IF(OR(A23 = "BG",A23 = "GR",A23 = "IT",A23 = "ES",A23 = "PT",A23 = "TR", A23 = "KR",A23 = "SE",A23 = "CH",A23 = "NO",A23 = "DK",A23 = "FI"), 1, 0) -> 1 | W23: =V23*H23 -> 5.1 | X23: =V23*J23 -> 3.1 | Y23: =IF(OR(A23 = "US",A23 = "CA",A23 = "UK",A23 = "NZ",A23 = "AU",A23 = "SG"), 1, 0) -> 0 | Z23: =VLOOKUP(R23,CPI!$A$2:$F$71,6,0) -> 1.47721 | AA23: =T23*Z23 -> 1016.0693 | AB23: =U23*Z23 -> 199.22928 | AC23: Media | AD23: https://www.novinite.com/articles/167648/Subway+Trains+to+Sofia+Airport+Start+Running+at+1+pm+on+April+2
A24: BH | B24: Bahrain | C24: Phase 1 | D24: Phase 1 (Red & Blue) | E24: 2018 | F24: 2023 | G24: 1 | H24: 28.6 | I24: =J24/H24 -> 0 | J24: 0 | K24: 0 | L24: 0 | M24: 20 | P24: 453 | Q24: BD | R24: 2019 | S24: =1/0.2 -> 5 | T24: =P24*S24 -> 2265 | U24: =T24/H24 -> 79.195804 | V24: =IF(OR(A24 = "BG",A24 = "GR",A24 = "IT",A24 = "ES",A24 = "PT",A24 = "TR", A24 = "KR",A24 = "SE",A24 = "CH",A24 = "NO",A24 = "DK",A24 = "FI"), 1, 0) -> 0 | W24: =V24*H24 -> 0 | X24: =V24*J24 -> 0 | Y24: =IF(OR(A24 = "US",A24 = "CA",A24 = "UK",A24 = "NZ",A24 = "AU",A24 = "SG"), 1, 0) -> 0 | Z24: =VLOOKUP(R24,CPI!$A$2:$F$71,6,0) -> 1.2599479 | AA24: =T24*Z24 -> 2853.782 | AB24: =U24*Z24 -> 99.782587 | AC24: Media | AD24: https://www.urbantransportnews.com/bahrain-to-finalise-109-km-light-metro-rail-bids-in-march-2020/
A25: BH | B25: Bahrain | C25: Phase 2 | D25: Phase 2 | E25: 2020 | F25: X | G25: 1 | H25: 72.7 | I25: =J25/H25 -> 0 | J25: 0 | K25: 0 | L25: 0 | P25: 1500 | Q25: BD | R25: 2010 | S25: =1/0.2 -> 5 | T25: =P25*S25 -> 7500 | U25: =T25/H25 -> 103.16369 | V25: =IF(OR(A25 = "BG",A25 = "GR",A25 = "IT",A25 = "ES",A25 = "PT",A25 = "TR", A25 = "KR",A25 = "SE",A25 = "CH",A25 = "NO",A25 = "DK",A25 = "FI"), 1, 0) -> 0 | W25: =V25*H25 -> 0 | X25: =V25*J25 -> 0 | Y25: =IF(OR(A25 = "US",A25 = "CA",A25 = "UK",A25 = "NZ",A25 = "AU",A25 = "SG"), 1, 0) -> 0 | Z25: =VLOOKUP(R25,CPI!$A$2:$F$71,6,0) -> 1.47721 | AA25: =T25*Z25 -> 11079.075 | AB25: =U25*Z25 -> 152.39443 | AC25: Media | AD25: http://www.tradearabia.com/news/stn_178416.html
A26: BR | B26: Rio de Janeiro | C26: Line 4 | D26: Line 4 | E26: 2010 | F26: 2016 | G26: 0 | H26: 16 | I26: 0.96 | J26: 15.4 | K26: 0 | L26: 0 | M26: 7 | O26: Measured | P26: 10300 | Q26: BRL | R26: 2013 | S26: 0.59 | T26: =P26*S26 -> 6077 | U26: =T26/H26 -> 379.8125 | V26: =IF(OR(A26 = "BG",A26 = "GR",A26 = "IT",A26 = "ES",A26 = "PT",A26 = "TR", A26 = "KR",A26 = "SE",A26 = "CH",A26 = "NO",A26 = "DK",A26 = "FI"), 1, 0) -> 0 | W26: =V26*H26 -> 0 | X26: =V26*J26 -> 0 | Y26: =IF(OR(A26 = "US",A26 = "CA",A26 = "UK",A26 = "NZ",A26 = "AU",A26 = "SG"), 1, 0) -> 0 | Z26: =VLOOKUP(R26,CPI!$A$2:$F$71,6,0) -> 1.3827208 | AA26: =T26*Z26 -> 8402.7946 | AB26: =U26*Z26 -> 525.17466 | AC26: Trade | AD26: http://itdpbrasil.org.br/wp-content/uploads/2018/05/ITDP_PP_Linha_4_Maio_2018.pdf
A27: BR | B27: Salvador | C27: Lines 1-2 | D27: Lines 1-2 | E27: 2000 | F27: 2017 | G27: 0 | H27: 33 | I27: 0.04 | J27: 1.4 | K27: 10.935 | L27: 20.745 | M27: 20 | O27: Wiki | P27: 4800 | Q27: BRL | R27: 2012 | S27: 0.62 | T27: =P27*S27 -> 2976 | U27: =T27/H27 -> 90.181818 | V27: =IF(OR(A27 = "BG",A27 = "GR",A27 = "IT",A27 = "ES",A27 = "PT",A27 = "TR", A27 = "KR",A27 = "SE",A27 = "CH",A27 = "NO",A27 = "DK",A27 = "FI"), 1, 0) -> 0 | W27: =V27*H27 -> 0 | X27: =V27*J27 -> 0 | Y27: =IF(OR(A27 = "US",A27 = "CA",A27 = "UK",A27 = "NZ",A27 = "AU",A27 = "SG"), 1, 0) -> 0 | Z27: =VLOOKUP(R27,CPI!$A$2:$F$71,6,0) -> 1.4029744 | AA27: =T27*Z27 -> 4175.2518 | AB27: =U27*Z27 -> 126.52278 | AC27: Media | AD27: http://patrocinados.estadao.com.br/ccr/salvadors-subway-becomes-a-model-of-success/
A28: BR | B28: Salvador | C28: SkyRail Bahia | D28: SkyRail Bahia | E28: 2020 | F28: 2022 | G28: 0 | H28: 23.3 | I28: 0 | J28: 0 | K28: 0 | L28: 0 | M28: 26 | O28: Trade | P28: 689 | Q28: USD | R28: 2021 | S28: 2.3 | T28: =P28*S28 -> 1584.7 | U28: =T28/H28 -> 68.012876 | V28: =IF(OR(A28 = "BG",A28 = "GR",A28 = "IT",A28 = "ES",A28 = "PT",A28 = "TR", A28 = "KR",A28 = "SE",A28 = "CH",A28 = "NO",A28 = "DK",A28 = "FI"), 1, 0) -> 0 | W28: =V28*H28 -> 0 | X28: =V28*J28 -> 0 | Y28: =IF(OR(A28 = "US",A28 = "CA",A28 = "UK",A28 = "NZ",A28 = "AU",A28 = "SG"), 1, 0) -> 0 | Z28: =VLOOKUP(R28,CPI!$A$2:$F$71,6,0) -> 1.188746 | AA28: =T28*Z28 -> 1883.8058 | AB28: =U28*Z28 -> 80.850033 | AC28: Trade | AD28: https://www.yicaiglobal.com/news/byd-design-for-usd689-million-brazil-monorail-gets-green-light
A29: BR | B29: Sao Paulo | C29: Line 5 | D29: Line 5 extension | E29: 2010 | F29: 2019 | G29: 0 | H29: 12 | I29: 1 | J29: 12 | K29: 0 | L29: 0 | M29: 11 | O29: Wiki | P29: 6900 | Q29: BRL | R29: 2014 | S29: 0.55 | T29: =P29*S29 -> 3795 | U29: =T29/H29 -> 316.25 | V29: =IF(OR(A29 = "BG",A29 = "GR",A29 = "IT",A29 = "ES",A29 = "PT",A29 = "TR", A29 = "KR",A29 = "SE",A29 = "CH",A29 = "NO",A29 = "DK",A29 = "FI"), 1, 0) -> 0 | W29: =V29*H29 -> 0 | X29: =V29*J29 -> 0 | Y29: =IF(OR(A29 = "US",A29 = "CA",A29 = "UK",A29 = "NZ",A29 = "AU",A29 = "SG"), 1, 0) -> 0 | Z29: =VLOOKUP(R29,CPI!$A$2:$F$71,6,0) -> 1.3606486 | AA29: =T29*Z29 -> 5163.6613 | AB29: =U29*Z29 -> 430.30511 | AC29: Trade | AD29: https://www.bnamericas.com/en/news/brazil-metro-cost-overruns-top-us9bn1
A30: BR | B30: Sao Paulo | C30: Line 17 | D30: Line 17 | E30: 2012 | F30: 2021 | G30: 0 | H30: 7.7 | I30: 0 | J30: 0 | K30: 0 | L30: 0 | M30: 8 | O30: Trade | P30: 1300 | Q30: USD | R30: 2016 | S30: 2.3 | T30: =P30*S30 -> 2990 | U30: =T30/H30 -> 388.31169 | V30: =IF(OR(A30 = "BG",A30 = "GR",A30 = "IT",A30 = "ES",A30 = "PT",A30 = "TR", A30 = "KR",A30 = "SE",A30 = "CH",A30 = "NO",A30 = "DK",A30 = "FI"), 1, 0) -> 0 | W30: =V30*H30 -> 0 | X30: =V30*J30 -> 0 | Y30: =IF(OR(A30 = "US",A30 = "CA",A30 = "UK",A30 = "NZ",A30 = "AU",A30 = "SG"), 1, 0) -> 0 | Z30: =VLOOKUP(R30,CPI!$A$2:$F$71,6,0) -> 1.3421046 | AA30: =T30*Z30 -> 4012.8928 | AB30: =U30*Z30 -> 521.15491 | AC30: Trade | AD30: https://www.railjournal.com/in_depth/21-rail-projects-to-watch-in-2021
A31: BR | B31: Sao Paulo | C31: Line 6 | D31: Line 6 phase 1 | E31: 2015 | F31: 2023 | G31: 0 | H31: 15.9 | I31: 0.84 | J31: 13.4 | K31: 0 | L31: 0 | M31: 15 | O31: Trade | P31: 9600 | Q31: BRL | R31: 2020 | S31: 0.44 | T31: =P31*S31 -> 4224 | U31: =T31/H31 -> 265.66038 | V31: =IF(OR(A31 = "BG",A31 = "GR",A31 = "IT",A31 = "ES",A31 = "PT",A31 = "TR", A31 = "KR",A31 = "SE",A31 = "CH",A31 = "NO",A31 = "DK",A31 = "FI"), 1, 0) -> 0 | W31: =V31*H31 -> 0 | X31: =V31*J31 -> 0 | Y31: =IF(OR(A31 = "US",A31 = "CA",A31 = "UK",A31 = "NZ",A31 = "AU",A31 = "SG"), 1, 0) -> 0 | Z31: =VLOOKUP(R31,CPI!$A$2:$F$71,6,0) -> 1.2445935 | AA31: =T31*Z31 -> 5257.1631 | AB31: =U31*Z31 -> 330.63919 | AC31: Trade | AD31: https://www.railjournal.com/passenger/metros/revival-of-sao-paulo-metro-line-6-orange-project-a-step-closer/
A32: CA | B32: Calgary | C32: Green Line | D32: Green Line stage 1 | E32: 2021 | F32: 2027 | G32: 0 | H32: 20 | I32: 0.2 | J32: 4 | K32: 0 | L32: 0 | M32: 15 | O32: Wiki | P32: 5500 | Q32: CAD | R32: 2024 | S32: 0.84 | T32: =P32*S32 -> 4620 | U32: =T32/H32 -> 231 | V32: =IF(OR(A32 = "BG",A32 = "GR",A32 = "IT",A32 = "ES",A32 = "PT",A32 = "TR", A32 = "KR",A32 = "SE",A32 = "CH",A32 = "NO",A32 = "DK",A32 = "FI"), 1, 0) -> 0 | W32: =V32*H32 -> 0 | X32: =V32*J32 -> 0 | Y32: =IF(OR(A32 = "US",A32 = "CA",A32 = "UK",A32 = "NZ",A32 = "AU",A32 = "SG"), 1, 0) -> 1 | Z32: =VLOOKUP(R32,CPI!$A$2:$F$71,6,0) -> 1 | AA32: =T32*Z32 -> 4620 | AB32: =U32*Z32 -> 231 | AC32: Media | AD32: https://globalnews.ca/news/7527443/green-line-lrt-calgary-alberta-government/
A33: CA | B33: Edmonton | C33: Valley Line Southeast | D33: Southeast | E33: 2016 | F33: 2023 | G33: 0 | H33: 13.1 | I33: 0.03 | J33: 0.4 | M33: 12 | N33: 125 | O33: Wiki | P33: 1800 | Q33: CAD | R33: 2019 | S33: 0.802 | T33: =P33*S33 -> 1443.6 | U33: =T33/H33 -> 110.19847 | V33: =IF(OR(A33 = "BG",A33 = "GR",A33 = "IT",A33 = "ES",A33 = "PT",A33 = "TR", A33 = "KR",A33 = "SE",A33 = "CH",A33 = "NO",A33 = "DK",A33 = "FI"), 1, 0) -> 0 | W33: =V33*H33 -> 0 | X33: =V33*J33 -> 0 | Y33: =IF(OR(A33 = "US",A33 = "CA",A33 = "UK",A33 = "NZ",A33 = "AU",A33 = "SG"), 1, 0) -> 1 | Z33: =VLOOKUP(R33,CPI!$A$2:$F$71,6,0) -> 1.2599479 | AA33: =T33*Z33 -> 1818.8608 | AB33: =U33*Z33 -> 138.84433 | AC33: Media | AD33: https://edmontonjournal.com/news/local-news/long-delayed-1-8-billion-valley-line-lrt-stymied-yet-again
A34: CA | B34: Edmonton | C34: Metro Line Extension | D34: Northwest Phase 1 | E34: 2020 | F34: 2024 | G34: 0 | H34: 1.6 | I34: 0 | J34: 0 | K34: 0 | L34: 1.6 | M34: 2 | N34: 125 | O34: Plan | P34: 291 | Q34: CAD | R34: 2020 | S34: 0.81 | T34: =P34*S34 -> 235.71 | U34: =T34/H34 -> 147.31875 | Y34: 1 | Z34: =VLOOKUP(R34,CPI!$A$2:$F$71,6,0) -> 1.2445935 | AA34: =T34*Z34 -> 293.36314 | AB34: =U34*Z34 -> 183.35197 | AD34: https://www.edmonton.ca/projects_plans/transit/nw-lrt https://tam-america.com/article/edmonton-metro-northwest-lrt-extension-phase-completed-on-budget-before-time#:~:text=Phase%201%20construction%20was%20originally,million%20(US%24215%20million).
A35: CA | B35: Edmonton | C35: Valley Line Extension | D35: West | E35: 2022 | F35: 2028 | G35: 0 | H35: 14 | I35: 0 | J35: 0 | K35: 2.1 | L35: =14-2.1 -> 11.9 | M35: 14 | N35: 125 | O35: Plan | P35: 2700 | Q35: CAD | R35: 2022 | S35: 0.88 | T35: =P35*S35 -> 2376 | U35: =T35/H35 -> 169.71429 | V35: 0 | Y35: 1 | Z35: =VLOOKUP(R35,CPI!$A$2:$F$71,6,0) -> 1.1006629 | AA35: =T35*Z35 -> 2615.175 | AB35: =U35*Z35 -> 186.79822 | AC35: Media | AD35: https://majorprojects.alberta.ca/details/Valley-Line-West-LRT/3692 https://www.operis.com/case-study/edmonton-valley-line-west/
A36: CA | B36: Hamilton | C36: Hamilton LRT | D36: Phase 1 | E36: 2025 | F36: 2029 | G36: 0 | H36: 14 | I36: 0 | J36: 0 | K36: 0 | L36: 14 | M36: 17 | N36: 50 | O36: Plan | P36: 3400 | Q36: CAD | R36: 2025 | S36: 1 | T36: =P36*S36 -> 3400 | U36: =T36/H36 -> 242.85714 | Z36: =VLOOKUP(R36,CPI!$A$2:$F$71,6,0) -> 1 | AA36: =T36*Z36 -> 3400 | AB36: =U36*Z36 -> 242.85714 | AC36: Media | AD36: https://www.metrolinx.com/en/projects-and-programs/hamilton-lrt https://canada.constructconnect.com/dcn/news/infrastructure/2024/11/request-for-qualifications-issued-for-hamilton-lrt-project
A37: CA | B37: Mississauga | C37: Hazel McCallion LRT | D37: Phase 1 | E37: 2020 | F37: 2027 | G37: 0 | H37: 18 | I37: =(1/19)% -> 0.00052631579 | J37: 1 | L37: 18 | M37: 19 | N37: 50 | O37: Plan | P37: 4700 | Q37: CAD | R37: 2020 | S37: 0.84 | T37: =P37*S37 -> 3948 | U37: =T37/H37 -> 219.33333 | Z37: =VLOOKUP(R37,CPI!$A$2:$F$71,6,0) -> 1.2445935 | AA37: =T37*Z37 -> 4913.6553 | AB37: =U37*Z37 -> 272.98085 | AC37: Media | AD37: https://www.metrolinx.com/en/projects-and-programs/hazel-mccallion-lrt/faqs
A38: CA | B38: Montreal | C38: Laval extension | D38: Laval extension | E38: 2001 | F38: 2007 | G38: 0 | H38: 5.2 | I38: 1 | J38: 5.2 | K38: 0 | L38: 0 | M38: 3 | O38: Wiki | P38: 745 | Q38: CAD | R38: 2004 | S38: 0.81 | T38: =P38*S38 -> 603.45 | U38: =T38/H38 -> 116.04808 | V38: =IF(OR(A38 = "BG",A38 = "GR",A38 = "IT",A38 = "ES",A38 = "PT",A38 = "TR", A38 = "KR",A38 = "SE",A38 = "CH",A38 = "NO",A38 = "DK",A38 = "FI"), 1, 0) -> 0 | W38: =V38*H38 -> 0 | X38: =V38*J38 -> 0 | Y38: =IF(OR(A38 = "US",A38 = "CA",A38 = "UK",A38 = "NZ",A38 = "AU",A38 = "SG"), 1, 0) -> 1 | Z38: =VLOOKUP(R38,CPI!$A$2:$F$71,6,0) -> 1.7052118 | AA38: =T38*Z38 -> 1029.01 | AB38: =U38*Z38 -> 197.88654 | AC38: Media | AD38: https://montrealgazette.com/news/local-news/the-sleepy-success-story-of-the-laval-metro-extension
A39: CA | B39: Montreal | C39: Blue Line | D39: Blue Line | E39: 2020 | F39: 2026 | G39: 0 | H39: 5.8 | I39: 1 | J39: 5.8 | K39: 0 | L39: 0 | M39: 5 | O39: Media | P39: 7600 | Q39: CAD | R39: 2018 | S39: 0.84 | T39: =P39*S39 -> 6384 | U39: =T39/H39 -> 1100.6897 | V39: =IF(OR(A39 = "BG",A39 = "GR",A39 = "IT",A39 = "ES",A39 = "PT",A39 = "TR", A39 = "KR",A39 = "SE",A39 = "CH",A39 = "NO",A39 = "DK",A39 = "FI"), 1, 0) -> 0 | W39: =V39*H39 -> 0 | X39: =V39*J39 -> 0 | Y39: =IF(OR(A39 = "US",A39 = "CA",A39 = "UK",A39 = "NZ",A39 = "AU",A39 = "SG"), 1, 0) -> 1 | Z39: =VLOOKUP(R39,CPI!$A$2:$F$71,6,0) -> 1.2827779 | AA39: =T39*Z39 -> 8189.2539 | AB39: =U39*Z39 -> 1411.9403 | AC39: Media | AD39: https://montrealgazette.com/news/local-news/montreal-metro-green-light-for-blue-line-extension https://www.cbc.ca/news/canada/montreal/blue-line-extension-delayed-1.7303767
A40: CA | B40: Montreal | C40: PSE | D40: Phase 1 | E40: 2025 | F40: 2033 | G40: 0 | H40: 31 | I40: 0 | J40: 0 | K40: 0 | L40: 31 | M40: 36/22 | O40: Plan | P40: 19000 | Q40: CAD | R40: 2025 | S40: 1 | T40: 19000 | U40: =T40/H40 -> 612.90323 | Y40: 0 | Z40: =VLOOKUP(R40,CPI!$A$2:$F$71,6,0) -> 1 | AA40: =T40*Z40 -> 19000 | AB40: =U40*Z40 -> 612.90323 | AC40: Media | AD40: https://www.cbc.ca/news/canada/montreal/public-transit-project-announcement-eastern-montreal-1.7475018 https://www.artm.quebec/wp-content/uploads/2024/05/RP_PSE_AC_VFinale_2024-05-28.pdf
A41: CA | B41: Ottawa | C41: Confederation | D41: Confederation | E41: 2013 | F41: 2019 | G41: 0 | H41: 12.5 | I41: 0.2 | J41: 2.5 | K41: 0.84 | L41: 9.16 | M41: 13 | N41: 90/120 | O41: Trade | P41: 2100 | Q41: CAD | R41: 2016 | S41: 0.83 | T41: =P41*S41 -> 1743 | U41: =T41/H41 -> 139.44 | V41: =IF(OR(A41 = "BG",A41 = "GR",A41 = "IT",A41 = "ES",A41 = "PT",A41 = "TR", A41 = "KR",A41 = "SE",A41 = "CH",A41 = "NO",A41 = "DK",A41 = "FI"), 1, 0) -> 0 | W41: =V41*H41 -> 0 | X41: =V41*J41 -> 0 | Y41: =IF(OR(A41 = "US",A41 = "CA",A41 = "UK",A41 = "NZ",A41 = "AU",A41 = "SG"), 1, 0) -> 1 | Z41: =VLOOKUP(R41,CPI!$A$2:$F$71,6,0) -> 1.3421046 | AA41: =T41*Z41 -> 2339.2883 | AB41: =U41*Z41 -> 187.14307 | AC41: Trade | AD41: https://www.aecom.com/projects/ottawa-light-rail/
A42: CA | B42: Ottawa | C42: Confederation | D42: East West Extensions | E42: 2019 | F42: 2025 | G42: 0 | H42: 28 | I42: =(3.4/28) -> 0.12142857 | J42: 3.4 | K42: 0 | L42: 12 | M42: 17 | N42: 90/120 | O42: Plan | P42: 2600 | Q42: CAD | R42: 2019 | S42: 0.802 | T42: =P42*S42 -> 2085.2 | U42: =T42/H42 -> 74.471429 | Y42: 1 | Z42: =VLOOKUP(R42,CPI!$A$2:$F$71,6,0) -> 1.2599479 | AA42: =T42*Z42 -> 2627.2434 | AB42: =U42*Z42 -> 93.83012 | AC42: Trade | AD42: https://www.kiewit.com/projects/ottawa-lrt-stage-2/ https://pub-ottawa.escribemeetings.com/filestream.ashx?documentid=58389 https://delveunderground.com/projects/ottawa-light-rail-transit-stages-1-and-2
A43: CA | B43: Ottawa | C43: Line 2/Line 4 | D43: South Extension+Airport Link | E43: 2020 | F43: 2025 | G43: 0 | H43: 20 | I43: 0 | J43: 0 | K43: 0.5 | L43: 15.5 | M43: 13 | N43: 90/120 | O43: Plan | P43: 1660 | Q43: CAD | R43: 2019 | S43: 0.802 | T43: =P43*S43 -> 1331.32 | U43: =T43/H43 -> 66.566 | Z43: =VLOOKUP(R43,CPI!$A$2:$F$71,6,0) -> 1.2599479 | AA43: =T43*Z43 -> 1677.3938 | AB43: =U43*Z43 -> 83.869692 | AC43: Media | AD43: https://www.renewcanada.net/ottawa-proceeding-with-4-67-billion-stage-2-lrt/ https://www.atkinsrealis.com/en/projects/o-train-extension
A44: CA | B44: Toronto | C44: Sheppard | D44: Sheppard | E44: 1994 | F44: 2002 | G44: 0 | H44: 5.5 | I44: 1 | J44: 5.5 | K44: 0 | L44: 0 | M44: 5 | O44: Media | P44: 1000 | Q44: CAD | R44: 1998 | S44: 0.81 | T44: =P44*S44 -> 810 | U44: =T44/H44 -> 147.27273 | V44: =IF(OR(A44 = "BG",A44 = "GR",A44 = "IT",A44 = "ES",A44 = "PT",A44 = "TR", A44 = "KR",A44 = "SE",A44 = "CH",A44 = "NO",A44 = "DK",A44 = "FI"), 1, 0) -> 0 | W44: =V44*H44 -> 0 | X44: =V44*J44 -> 0 | Y44: =IF(OR(A44 = "US",A44 = "CA",A44 = "UK",A44 = "NZ",A44 = "AU",A44 = "SG"), 1, 0) -> 1 | Z44: =VLOOKUP(R44,CPI!$A$2:$F$71,6,0) -> 1.9761626 | AA44: =T44*Z44 -> 1600.6917 | AB44: =U44*Z44 -> 291.03485 | AC44: Media | AD44: https://www.theglobeandmail.com/news/toronto/sheppard-subway-extension-a-quarter-the-stops-for-three-times-the-cost/article622366/
A45: CA | B45: Toronto | C45: YUS | D45: Vaughan | E45: 2009 | F45: 2017 | G45: 0 | H45: 8.6 | I45: 1 | J45: 8.6 | K45: 0 | L45: 0 | M45: 6 | O45: Media | P45: 3200 | Q45: CAD | R45: 2013 | S45: 0.81 | T45: =P45*S45 -> 2592 | U45: =T45/H45 -> 301.39535 | V45: =IF(OR(A45 = "BG",A45 = "GR",A45 = "IT",A45 = "ES",A45 = "PT",A45 = "TR", A45 = "KR",A45 = "SE",A45 = "CH",A45 = "NO",A45 = "DK",A45 = "FI"), 1, 0) -> 0 | W45: =V45*H45 -> 0 | X45: =V45*J45 -> 0 | Y45: 1 | Z45: =VLOOKUP(R45,CPI!$A$2:$F$71,6,0) -> 1.3827208 | AA45: =T45*Z45 -> 3584.0124 | AB45: =U45*Z45 -> 416.74563 | AC45: Media | AD45: https://www.thestar.com/news/gta/transportation/2017/12/15/trudeau-wynne-tory-on-hand-to-cut-ribbon-on-32-billion-subway-extension.html
...

Sheet 1_16_2026
A1: d | B1: Country | C1: City | D1: Line | E1: Phase | F1: Start year | G1: End year | H1: RR? | I1: Length | J1: TunnelPer | K1: Tunnel | L1: Elevated | M1: Atgrade | N1: Stations | O1: Platform Length (Meters) | P1: Source1 | Q1: Cost | R1: Currency | S1: Year | T1: PPP rate | U1: Real cost | V1: Cost/km (Millions) | W1: Cheap? | X1: Clength | Y1: Ctunnel | Z1: Anglo? | AA1: Inflation Index | AB1: Real cost (2023 dollars) | AC1: Cost/km (2023 dollars)
A2: 8200 | B2: AE | C2: Dubai | D2: Phase 1 | E2: Phase 1 - Red Line | F2: 2005 | G2: 2010 | H2: 0 | I2: 35 | J2: =K2/I2 -> 0.13428571 | K2: 4.7 | L2: 0 | M2: 0 | N2: 29 | P2: Trade | Q2: 4200 | R2: USD | S2: 2005 | T2: 1.8 | U2: =Q2*T2 -> 7560 | V2: =U2/I2 -> 216 | W2: =IF(OR(B2 = "BG",B2 = "GR",B2 = "IT",B2 = "ES",B2 = "PT",B2 = "TR", B2 = "KR",B2 = "SE",B2 = "CH",B2 = "NO",B2 = "DK",B2 = "FI"), 1, 0) -> 0 | X2: =W2*I2 -> 0 | Y2: =W2*K2 -> 0 | Z2: =IF(OR(B2 = "US",B2 = "CA",B2 = "UK",B2 = "NZ",B2 = "AU",B2 = "SG"), 1, 0) -> 0 | AA2: =VLOOKUP(S2,CPI!$A$2:$E$67,5,0) -> 1.5601741 | AB2: =U2*AA2 -> 11794.916 | AC2: =V2*AA2 -> 336.9976
A3: 8201 | B3: AE | C3: Dubai | D3: Phase 2 | E3: Phase 2 - Green Line | F3: 2006 | G3: 2010 | H3: 0 | I3: 22.5 | J3: =K3/I3 -> 0.35111111 | K3: 7.9 | L3: 0 | M3: 0 | N3: 20 | Q3: 3600 | R3: USD | S3: 2006 | T3: 1.9 | U3: =Q3*T3 -> 6840 | V3: =U3/I3 -> 304 | W3: =IF(OR(B3 = "BG",B3 = "GR",B3 = "IT",B3 = "ES",B3 = "PT",B3 = "TR", B3 = "KR",B3 = "SE",B3 = "CH",B3 = "NO",B3 = "DK",B3 = "FI"), 1, 0) -> 0 | X3: =W3*I3 -> 0 | Y3: =W3*K3 -> 0 | Z3: =IF(OR(B3 = "US",B3 = "CA",B3 = "UK",B3 = "NZ",B3 = "AU",B3 = "SG"), 1, 0) -> 0 | AA3: =VLOOKUP(S3,CPI!$A$2:$E$67,5,0) -> 1.5114187 | AB3: =U3*AA3 -> 10338.104 | AC3: =V3*AA3 -> 459.47127
